<?xml version="1.0" ?>
<!-- =================================================================================== -->
<!-- |    This document was autogenerated by xacro from src/team12_description/urdf/team12_amr.xacro | -->
<!-- |    EDITING THIS FILE BY HAND IS NOT RECOMMENDED                                 | -->
<!-- =================================================================================== -->
<robot name="team12_robot">
  <!-- ================= INERTIA MACROS ================= -->
  <!-- ================= MATERIALS ================= -->
  <material name="grey">
    <color rgba="0.6 0.6 0.6 1.0"/>
  </material>
  <material name="black">
    <color rgba="0.05 0.05 0.05 1.0"/>
  </material>
  <material name="blue">
    <color rgba="0.0 0.2 0.8 1.0"/>
  </material>
  <!-- ================= BASE LINK ================= -->
  <link name="base_link"/>
  <!-- ================= CHASSIS ================= -->
  <link name="chassis_link">
    <inertial>
      <mass value="15.0"/>
      <origin xyz="0 0 0"/>
      <inertia ixx="0.190625" ixy="0.0" ixz="0.0" iyy="0.342625" iyz="0.0" izz="0.377"/>
    </inertial>
    <visual>
      <origin rpy="0 0 0" xyz="0 0 0"/>
      <geometry>
        <mesh filename="package://team12_description/meshes/chassis.stl" scale="0.001 0.001 0.001"/>
      </geometry>
      <material name="grey"/>
    </visual>
    <collision>
      <origin rpy="0 0 0" xyz="0 0 0"/>
      <geometry>
        <mesh filename="package://team12_description/meshes/chassis.stl" scale="0.001 0.001 0.001"/>
      </geometry>
    </collision>
  </link>
  <joint name="base_joint" type="fixed">
    <parent link="base_link"/>
    <child link="chassis_link"/>
    <origin rpy="0 0 0" xyz="0 0 0.10"/>
  </joint>
  <!-- ================= WHEEL MACRO ================= -->
  <!-- ================= WHEELS ================= -->
  <link name="front_left_wheel_link">
    <inertial>
      <mass value="2.0"/>
      <origin xyz="0 0 0"/>
      <inertia ixx="0.005416666666666668" ixy="0.0" ixz="0.0" iyy="0.010000000000000002" iyz="0.0" izz="0.005416666666666668"/>
    </inertial>
    <visual>
      <origin rpy="1.5708 0 0" xyz="0 0 0"/>
      <geometry>
        <cylinder length="0.05" radius="0.10"/>
      </geometry>
      <material name="black"/>
    </visual>
    <collision>
      <origin rpy="1.5708 0 0" xyz="0 0 0"/>
      <geometry>
        <cylinder length="0.05" radius="0.10"/>
      </geometry>
    </collision>
  </link>
  <joint name="front_left_wheel_joint" type="continuous">
    <parent link="chassis_link"/>
    <child link="front_left_wheel_link"/>
    <origin rpy="0 0 0" xyz="0.2 0.15 -0.10"/>
    <axis xyz="0 1 0"/>
  </joint>
  <!-- Gazebo friction -->
  <gazebo reference="front_left_wheel_link">
    <mu1>1.0</mu1>
    <mu2>1.0</mu2>
    <kp>100000.0</kp>
    <kd>1.0</kd>
  </gazebo>
  <link name="front_right_wheel_link">
    <inertial>
      <mass value="2.0"/>
      <origin xyz="0 0 0"/>
      <inertia ixx="0.005416666666666668" ixy="0.0" ixz="0.0" iyy="0.010000000000000002" iyz="0.0" izz="0.005416666666666668"/>
    </inertial>
    <visual>
      <origin rpy="1.5708 0 0" xyz="0 0 0"/>
      <geometry>
        <cylinder length="0.05" radius="0.10"/>
      </geometry>
      <material name="black"/>
    </visual>
    <collision>
      <origin rpy="1.5708 0 0" xyz="0 0 0"/>
      <geometry>
        <cylinder length="0.05" radius="0.10"/>
      </geometry>
    </collision>
  </link>
  <joint name="front_right_wheel_joint" type="continuous">
    <parent link="chassis_link"/>
    <child link="front_right_wheel_link"/>
    <origin rpy="0 0 0" xyz="0.2 -0.15 -0.10"/>
    <axis xyz="0 1 0"/>
  </joint>
  <!-- Gazebo friction -->
  <gazebo reference="front_right_wheel_link">
    <mu1>1.0</mu1>
    <mu2>1.0</mu2>
    <kp>100000.0</kp>
    <kd>1.0</kd>
  </gazebo>
  <link name="rear_left_wheel_link">
    <inertial>
      <mass value="2.0"/>
      <origin xyz="0 0 0"/>
      <inertia ixx="0.005416666666666668" ixy="0.0" ixz="0.0" iyy="0.010000000000000002" iyz="0.0" izz="0.005416666666666668"/>
    </inertial>
    <visual>
      <origin rpy="1.5708 0 0" xyz="0 0 0"/>
      <geometry>
        <cylinder length="0.05" radius="0.10"/>
      </geometry>
      <material name="black"/>
    </visual>
    <collision>
      <origin rpy="1.5708 0 0" xyz="0 0 0"/>
      <geometry>
        <cylinder length="0.05" radius="0.10"/>
      </geometry>
    </collision>
  </link>
  <joint name="rear_left_wheel_joint" type="continuous">
    <parent link="chassis_link"/>
    <child link="rear_left_wheel_link"/>
    <origin rpy="0 0 0" xyz="-0.2 0.15 -0.10"/>
    <axis xyz="0 1 0"/>
  </joint>
  <!-- Gazebo friction -->
  <gazebo reference="rear_left_wheel_link">
    <mu1>1.0</mu1>
    <mu2>1.0</mu2>
    <kp>100000.0</kp>
    <kd>1.0</kd>
  </gazebo>
  <link name="rear_right_wheel_link">
    <inertial>
      <mass value="2.0"/>
      <origin xyz="0 0 0"/>
      <inertia ixx="0.005416666666666668" ixy="0.0" ixz="0.0" iyy="0.010000000000000002" iyz="0.0" izz="0.005416666666666668"/>
    </inertial>
    <visual>
      <origin rpy="1.5708 0 0" xyz="0 0 0"/>
      <geometry>
        <cylinder length="0.05" radius="0.10"/>
      </geometry>
      <material name="black"/>
    </visual>
    <collision>
      <origin rpy="1.5708 0 0" xyz="0 0 0"/>
      <geometry>
        <cylinder length="0.05" radius="0.10"/>
      </geometry>
    </collision>
  </link>
  <joint name="rear_right_wheel_joint" type="continuous">
    <parent link="chassis_link"/>
    <child link="rear_right_wheel_link"/>
    <origin rpy="0 0 0" xyz="-0.2 -0.15 -0.10"/>
    <axis xyz="0 1 0"/>
  </joint>
  <!-- Gazebo friction -->
  <gazebo reference="rear_right_wheel_link">
    <mu1>1.0</mu1>
    <mu2>1.0</mu2>
    <kp>100000.0</kp>
    <kd>1.0</kd>
  </gazebo>
  <!-- ================= LIDAR ================= -->
  <link name="lidar_link">
    <inertial>
      <mass value="0.5"/>
      <origin xyz="0 0 0"/>
      <inertia ixx="0.00041666666666666675" ixy="0.0" ixz="0.0" iyy="0.0006250000000000001" iyz="0.0" izz="0.00041666666666666675"/>
    </inertial>
    <visual>
      <origin rpy="0 0 0" xyz="0 0 0"/>
      <geometry>
        <cylinder length="0.05" radius="0.05"/>
      </geometry>
      <material name="blue"/>
    </visual>
    <collision>
      <geometry>
        <cylinder length="0.05" radius="0.05"/>
      </geometry>
    </collision>
  </link>
  <joint name="lidar_joint" type="fixed">
    <parent link="chassis_link"/>
    <child link="lidar_link"/>
    <origin rpy="0 0 0" xyz="0 0 0.23"/>
  </joint>
  <!-- ================= GAZEBO GLOBAL ================= -->
  <gazebo>
    <gravity>true</gravity>
  </gazebo>
</robot>
